# 启动分支节点w1，叶子节点w11和叶子节点w12

## 启动分支节点w1

首先修改节点初始化的脚本`w1_init.sh`。

```bash
#!/bin/sh

node_dir=../geth_w1

# 正常版本
geth-tree --identity "MyEth" --rpc --rpcport "8549" --rpccorsdomain "*" \
    --datadir "$node_dir/gethdata" --port "30309" --nodiscover \
    --rpcapi "eth,net,personal,web3,miner" --networkid "w1" \
    init "$node_dir/genesisgtrie.json"

# 无log
geth-tree --identity "MyEth" --rpc --rpcport "8549" --rpccorsdomain "*" \
    --datadir "$node_dir/gethdata" --port "30309" --nodiscover \
    --rpcapi "eth,net,personal,web3,miner" --networkid "w1" --syncmode "branch" \
    --allow-insecure-unlock --dev.period 1 --preload "w1_setbranch.js" console
```

终端中执行`sh w1_init.sh`即可启动节点。

## 启动叶子节点w11和w12

首先编辑`w11_1_addPeer.js`，将开头的`admin.addPeer`中的地址替换为w1 enode信息：

```js
admin.addPeer("enode://9382213a74dec4c63180a6869d6fae9006726ea26da84680b8eb223d9a08da6f8e674226a9b04ad7d602f882db442b495b415bfc7174b7323dbe11b8b8c04eb0@127.0.0.1:30309?discport=0")
// -- snip --
```

再将`w11_1_init.sh`修改为如下：

```bash
#!/bin/sh

node_dir=../geth_w11_1

geth-tree --identity "MyEth" --rpc --rpcport "8511" --rpccorsdomain "*" \
    --datadir "$node_dir/gethdata" --port "30311" --nodiscover \
    --rpcapi "eth,net,personal,web3,miner" --networkid "w11" \
    init "$node_dir/genesisgtrie.json"

geth-tree --identity "MyEth" --rpc --rpcport "8511" --rpccorsdomain "*" \
    --datadir "$node_dir/gethdata" --port "30311" --nodiscover \
    --rpcapi "eth,net,personal,web3,miner" --networkid "w11" --allow-insecure-unlock \
    --dev.period 1 --preload "w11_1_addPeer.js" console
```

终端执行`sh w11_1_init.sh`即可启动节点w11。

启动w12的过程和w11类似

输入admin.peers确认是否连接

# 进行实验

首先，在w11和w12中开启挖矿：

```js
// 在w11的终端中输入，开启挖矿
miner.start(1)
// 在w12的终端中输入，开启挖矿
miner.start(1)
```

然后，新建一个终端，在其中执行：
```bash
//分开
node w2_commontx.js
node w3_commontx.js
//合并
node sync_test.js
```

**发生错误！！** 执行`node w2_commontx.js`之后，节点w11就停止了工作，同时在运行node的终端出现了这样的报错信息：
```
(node:5690) ExperimentalWarning: The Fetch API is an experimental feature. This feature could change at any time
(Use `node --trace-warnings ...` to show where the warning was created)
/home/dyz/node_modules/web3-core-helpers/lib/errors.js:28
        var err = new Error('Returned error: ' + message);
                  ^

Error: Returned error: unknown account
    at Object.ErrorResponse (/home/dyz/node_modules/web3-core-helpers/lib/errors.js:28:19)
    at /home/dyz/node_modules/web3-core-requestmanager/lib/index.js:300:36
    at /home/dyz/node_modules/web3-providers-http/lib/index.js:124:13
    at process.processTicksAndRejections (node:internal/process/task_queues:95:5) {
  data: null
}

Node.js v18.12.1
```
显示是未知账户问题

同时主节点中出现主要问题

```
WARN [03-29|19:27:01.429] Header broke chain ancestry              number=200 hash=5efc5e…e9c382
WARN [03-29|19:27:01.429] Synchronisation failed, dropping peer    peer=3747184f6c5e9df9 err="action from bad peer ignored"
WARN [03-29|19:27:11.531] Header broke chain ancestry              peer=ace7a6260142d7e9 number=187 hash=87b339…1cdc9d
WARN [03-29|19:27:11.535] Synchronisation failed, dropping peer    peer=ace7a6260142d7e9 err="retrieved hash chain is invalid"
```
在上一步确认连接后，发现二者连接非常不稳定，出现这种“自动”断连的未知情况，手动调用admin.peers后显示为[ ]，之后才会又连接，但是发送转账请求后又出现这种不稳定的断连，

目前还没找到问题出现在何处



